<?xml version="1.0"?>
<!--
  Integration Humanoid Robot URDF

  Combines all Module 2 concepts:
  - Physics simulation (Chapter 1): Differential drive platform with wheels
  - Sensor simulation (Chapter 3): LiDAR, depth camera, IMU
  - Unity compatibility (Chapter 2): Materials and proper joint structure

  System architecture:
  - Base platform: Wheeled differential drive (cmd_vel → odom)
  - Torso: Vertical column for height
  - Sensors:
    * LiDAR (front): 270° scanning, /scan topic
    * Depth camera (head): RGB-D data, /camera/* topics
    * IMU (torso center): Acceleration/orientation, /imu topic
-->
<robot name="integration_humanoid">

  <!-- ===================== BASE PLATFORM ===================== -->
  <!-- Base Link (robot chassis) -->
  <link name="base_link">
    <visual>
      <geometry>
        <box size="0.6 0.4 0.2"/>  <!-- 60cm x 40cm x 20cm -->
      </geometry>
      <material name="gray">
        <color rgba="0.5 0.5 0.5 1.0"/>
      </material>
    </visual>
    <collision>
      <geometry>
        <box size="0.6 0.4 0.2"/>
      </geometry>
    </collision>
    <inertial>
      <mass value="15.0"/>  <!-- 15 kg chassis (heavier due to torso) -->
      <!-- Cuboid inertia for 60x40x20cm, 15kg -->
      <inertia ixx="0.225" ixy="0.0" ixz="0.0"
               iyy="0.375" iyz="0.0"
               izz="0.500"/>
    </inertial>
  </link>

  <!-- ===================== WHEELS ===================== -->
  <!-- Left Wheel -->
  <link name="left_wheel">
    <visual>
      <geometry>
        <cylinder radius="0.1" length="0.05"/>  <!-- 10cm radius, 5cm width -->
      </geometry>
      <material name="black">
        <color rgba="0.1 0.1 0.1 1.0"/>
      </material>
    </visual>
    <collision>
      <geometry>
        <cylinder radius="0.1" length="0.05"/>
      </geometry>
      <surface>
        <friction>
          <ode>
            <mu>1.0</mu>   <!-- High friction for traction -->
            <mu2>1.0</mu2>
          </ode>
        </friction>
      </surface>
    </collision>
    <inertial>
      <mass value="0.5"/>
      <inertia ixx="0.00146" ixy="0.0" ixz="0.0"
               iyy="0.00146" iyz="0.0"
               izz="0.0025"/>
    </inertial>
  </link>

  <!-- Right Wheel -->
  <link name="right_wheel">
    <visual>
      <geometry>
        <cylinder radius="0.1" length="0.05"/>
      </geometry>
      <material name="black">
        <color rgba="0.1 0.1 0.1 1.0"/>
      </material>
    </visual>
    <collision>
      <geometry>
        <cylinder radius="0.1" length="0.05"/>
      </geometry>
      <surface>
        <friction>
          <ode>
            <mu>1.0</mu>
            <mu2>1.0</mu2>
          </ode>
        </friction>
      </surface>
    </collision>
    <inertial>
      <mass value="0.5"/>
      <inertia ixx="0.00146" ixy="0.0" ixz="0.0"
               iyy="0.00146" iyz="0.0"
               izz="0.0025"/>
    </inertial>
  </link>

  <!-- Caster Wheel (passive support) -->
  <link name="caster_wheel">
    <visual>
      <geometry>
        <sphere radius="0.05"/>
      </geometry>
      <material name="white">
        <color rgba="0.9 0.9 0.9 1.0"/>
      </material>
    </visual>
    <collision>
      <geometry>
        <sphere radius="0.05"/>
      </geometry>
      <surface>
        <friction>
          <ode>
            <mu>0.1</mu>  <!-- Low friction for free rotation -->
            <mu2>0.1</mu2>
          </ode>
        </friction>
      </surface>
    </collision>
    <inertial>
      <mass value="0.2"/>
      <inertia ixx="0.0002" ixy="0.0" ixz="0.0"
               iyy="0.0002" iyz="0.0"
               izz="0.0002"/>
    </inertial>
  </link>

  <!-- Wheel Joints -->
  <joint name="left_wheel_joint" type="continuous">
    <parent link="base_link"/>
    <child link="left_wheel"/>
    <origin xyz="0.0 0.225 -0.1" rpy="-1.5708 0 0"/>
    <axis xyz="0 0 1"/>
    <dynamics damping="0.1" friction="0.1"/>
  </joint>

  <joint name="right_wheel_joint" type="continuous">
    <parent link="base_link"/>
    <child link="right_wheel"/>
    <origin xyz="0.0 -0.225 -0.1" rpy="-1.5708 0 0"/>
    <axis xyz="0 0 1"/>
    <dynamics damping="0.1" friction="0.1"/>
  </joint>

  <joint name="caster_wheel_joint" type="fixed">
    <parent link="base_link"/>
    <child link="caster_wheel"/>
    <origin xyz="0.25 0.0 -0.15" rpy="0 0 0"/>
  </joint>

  <!-- ===================== TORSO ===================== -->
  <link name="torso_link">
    <visual>
      <origin xyz="0 0 0.5" rpy="0 0 0"/>
      <geometry>
        <box size="0.3 0.2 1.0"/>  <!-- 30cm x 20cm x 100cm vertical column -->
      </geometry>
      <material name="white">
        <color rgba="0.9 0.9 0.9 1.0"/>
      </material>
    </visual>
    <collision>
      <origin xyz="0 0 0.5" rpy="0 0 0"/>
      <geometry>
        <box size="0.3 0.2 1.0"/>
      </geometry>
    </collision>
    <inertial>
      <origin xyz="0 0 0.5" rpy="0 0 0"/>
      <mass value="10.0"/>
      <!-- Cuboid inertia for 30x20x100cm, 10kg -->
      <inertia ixx="0.858" ixy="0.0" ixz="0.0"
               iyy="0.883" iyz="0.0"
               izz="0.108"/>
    </inertial>
  </link>

  <joint name="base_to_torso" type="fixed">
    <parent link="base_link"/>
    <child link="torso_link"/>
    <origin xyz="0 0 0.1" rpy="0 0 0"/>  <!-- Mount on top of base -->
  </joint>

  <!-- ===================== SENSORS ===================== -->

  <!-- LiDAR (front of base, elevated) -->
  <link name="lidar_link">
    <visual>
      <geometry>
        <cylinder radius="0.05" length="0.07"/>
      </geometry>
      <material name="black">
        <color rgba="0.1 0.1 0.1 1.0"/>
      </material>
    </visual>
    <collision>
      <geometry>
        <cylinder radius="0.05" length="0.07"/>
      </geometry>
    </collision>
    <inertial>
      <mass value="0.3"/>
      <inertia ixx="0.0001" ixy="0.0" ixz="0.0"
               iyy="0.0001" iyz="0.0"
               izz="0.0001"/>
    </inertial>
  </link>

  <joint name="base_to_lidar" type="fixed">
    <parent link="base_link"/>
    <child link="lidar_link"/>
    <origin xyz="0.3 0 0.15" rpy="0 0 0"/>  <!-- Front of base, 15cm above -->
  </joint>

  <!-- Depth Camera (head, top of torso) -->
  <link name="camera_link">
    <visual>
      <geometry>
        <box size="0.05 0.15 0.03"/>  <!-- RealSense-like dimensions -->
      </geometry>
      <material name="black">
        <color rgba="0.1 0.1 0.1 1.0"/>
      </material>
    </visual>
    <collision>
      <geometry>
        <box size="0.05 0.15 0.03"/>
      </geometry>
    </collision>
    <inertial>
      <mass value="0.2"/>
      <inertia ixx="0.0001" ixy="0.0" ixz="0.0"
               iyy="0.0001" iyz="0.0"
               izz="0.0001"/>
    </inertial>
  </link>

  <joint name="torso_to_camera" type="fixed">
    <parent link="torso_link"/>
    <child link="camera_link"/>
    <origin xyz="0.15 0 1.0" rpy="0 0 0"/>  <!-- Top of torso, facing forward -->
  </joint>

  <!-- IMU (center of torso) -->
  <link name="imu_link">
    <inertial>
      <mass value="0.01"/>
      <inertia ixx="0.00001" ixy="0.0" ixz="0.0"
               iyy="0.00001" iyz="0.0"
               izz="0.00001"/>
    </inertial>
  </link>

  <joint name="torso_to_imu" type="fixed">
    <parent link="torso_link"/>
    <child link="imu_link"/>
    <origin xyz="0 0 0.5" rpy="0 0 0"/>  <!-- Center of torso -->
  </joint>

  <!-- ===================== GAZEBO PLUGINS ===================== -->

  <!-- Differential Drive Controller -->
  <gazebo>
    <plugin name="diff_drive" filename="libgazebo_ros_diff_drive.so">
      <!-- Wheel joints -->
      <left_joint>left_wheel_joint</left_joint>
      <right_joint>right_wheel_joint</right_joint>

      <!-- Physical parameters -->
      <wheel_separation>0.45</wheel_separation>
      <wheel_diameter>0.2</wheel_diameter>
      <max_wheel_torque>20.0</max_wheel_torque>
      <max_wheel_acceleration>1.0</max_wheel_acceleration>

      <!-- ROS 2 Topics -->
      <command_topic>cmd_vel</command_topic>
      <odometry_topic>odom</odometry_topic>
      <odometry_frame>odom</odometry_frame>
      <robot_base_frame>base_link</robot_base_frame>

      <!-- Publishing -->
      <publish_odom>true</publish_odom>
      <publish_odom_tf>true</publish_odom_tf>
      <publish_wheel_tf>false</publish_wheel_tf>

      <update_rate>50.0</update_rate>
    </plugin>
  </gazebo>

  <!-- LiDAR Sensor Plugin -->
  <gazebo reference="lidar_link">
    <sensor name="lidar" type="ray">
      <pose>0 0 0 0 0 0</pose>
      <visualize>true</visualize>
      <update_rate>15</update_rate>
      <ray>
        <scan>
          <horizontal>
            <samples>1081</samples>
            <resolution>1</resolution>
            <min_angle>-2.35619</min_angle>  <!-- -135° -->
            <max_angle>2.35619</max_angle>   <!-- +135° -->
          </horizontal>
        </scan>
        <range>
          <min>0.05</min>
          <max>10.0</max>
          <resolution>0.01</resolution>
        </range>
        <noise>
          <type>gaussian</type>
          <mean>0.0</mean>
          <stddev>0.01</stddev>  <!-- 1cm noise (SICK TiM561 spec) -->
        </noise>
      </ray>
      <plugin name="lidar_plugin" filename="libgazebo_ros_ray_sensor.so">
        <ros>
          <remapping>~/out:=scan</remapping>
        </ros>
        <output_type>sensor_msgs/LaserScan</output_type>
        <frame_name>lidar_link</frame_name>
      </plugin>
    </sensor>
  </gazebo>

  <!-- Depth Camera Plugin -->
  <gazebo reference="camera_link">
    <sensor name="depth_camera" type="depth">
      <update_rate>30</update_rate>
      <camera>
        <horizontal_fov>1.5184</horizontal_fov>  <!-- 87° (RealSense D435i) -->
        <image>
          <width>640</width>
          <height>480</height>
          <format>R8G8B8</format>
        </image>
        <clip>
          <near>0.3</near>
          <far>10.0</far>
        </clip>
        <noise>
          <type>gaussian</type>
          <mean>0.0</mean>
          <stddev>0.007</stddev>  <!-- 7mm depth accuracy -->
        </noise>
      </camera>
      <plugin name="depth_camera_plugin" filename="libgazebo_ros_camera.so">
        <ros>
          <remapping>~/image_raw:=camera/rgb/image_raw</remapping>
          <remapping>~/depth/image_raw:=camera/depth/image_raw</remapping>
          <remapping>~/points:=camera/depth/points</remapping>
        </ros>
        <camera_name>depth_camera</camera_name>
        <frame_name>camera_link</frame_name>
      </plugin>
    </sensor>
  </gazebo>

  <!-- IMU Plugin -->
  <gazebo reference="imu_link">
    <sensor name="imu" type="imu">
      <always_on>true</always_on>
      <update_rate>100</update_rate>
      <plugin name="imu_plugin" filename="libgazebo_ros_imu_sensor.so">
        <ros>
          <remapping>~/out:=imu</remapping>
        </ros>
        <frame_name>imu_link</frame_name>
        <!-- MPU-6050 specifications -->
        <initial_orientation_as_reference>false</initial_orientation_as_reference>
        <angular_velocity_stdev>0.0035</angular_velocity_stdev>  <!-- ~0.2°/s -->
        <linear_acceleration_stdev>0.017</linear_acceleration_stdev>  <!-- ~0.17% of g -->
      </plugin>
    </sensor>
  </gazebo>

  <!-- Gazebo Materials -->
  <gazebo reference="base_link">
    <material>Gazebo/Gray</material>
  </gazebo>
  <gazebo reference="torso_link">
    <material>Gazebo/White</material>
  </gazebo>
  <gazebo reference="left_wheel">
    <material>Gazebo/Black</material>
    <mu1>1.0</mu1>
    <mu2>1.0</mu2>
  </gazebo>
  <gazebo reference="right_wheel">
    <material>Gazebo/Black</material>
    <mu1>1.0</mu1>
    <mu2>1.0</mu2>
  </gazebo>
  <gazebo reference="caster_wheel">
    <material>Gazebo/White</material>
    <mu1>0.1</mu1>
    <mu2>0.1</mu2>
  </gazebo>
  <gazebo reference="lidar_link">
    <material>Gazebo/Black</material>
  </gazebo>
  <gazebo reference="camera_link">
    <material>Gazebo/Black</material>
  </gazebo>

</robot>
